2022-11-04 02:05:00 ERROR Traceback (most recent call last):
  File "c:\users\leech\anaconda3\lib\site-packages\wandb\cli\cli.py", line 97, in wrapper
    return func(*args, **kwargs)
  File "c:\users\leech\anaconda3\lib\site-packages\wandb\cli\cli.py", line 241, in login
    wandb.login(relogin=relogin, key=key, anonymous=anon_mode, host=host, force=True)
  File "c:\users\leech\anaconda3\lib\site-packages\wandb\sdk\wandb_login.py", line 77, in login
    configured = _login(**kwargs)
  File "c:\users\leech\anaconda3\lib\site-packages\wandb\sdk\wandb_login.py", line 298, in _login
    wlogin.prompt_api_key()
  File "c:\users\leech\anaconda3\lib\site-packages\wandb\sdk\wandb_login.py", line 228, in prompt_api_key
    raise UsageError("api_key not configured (no-tty). call " + directive)
wandb.errors.UsageError: api_key not configured (no-tty). call wandb login [your_api_key]

